[2024-04-22T15:23:26.028+0000] {task_context_logger.py:104} ERROR - Executor reports task instance <TaskInstance: example_bash_operator.runme_1 scheduled__2024-04-21T00:00:00+00:00 [queued]> finished (failed) although the task says it's queued. (Info: None) Was the task killed externally?
